Traceback (most recent call last):
  File "/Library/Frameworks/Python.framework/Versions/3.10/lib/python3.10/site-packages/jupyter_cache/executors/utils.py", line 51, in single_nb_execution
    executenb(
  File "/Library/Frameworks/Python.framework/Versions/3.10/lib/python3.10/site-packages/nbclient/client.py", line 1204, in execute
    return NotebookClient(nb=nb, resources=resources, km=km, **kwargs).execute()
  File "/Library/Frameworks/Python.framework/Versions/3.10/lib/python3.10/site-packages/nbclient/util.py", line 84, in wrapped
    return just_run(coro(*args, **kwargs))
  File "/Library/Frameworks/Python.framework/Versions/3.10/lib/python3.10/site-packages/nbclient/util.py", line 62, in just_run
    return loop.run_until_complete(coro)
  File "/Library/Frameworks/Python.framework/Versions/3.10/lib/python3.10/asyncio/base_events.py", line 646, in run_until_complete
    return future.result()
  File "/Library/Frameworks/Python.framework/Versions/3.10/lib/python3.10/site-packages/nbclient/client.py", line 663, in async_execute
    await self.async_execute_cell(
  File "/Library/Frameworks/Python.framework/Versions/3.10/lib/python3.10/site-packages/nbclient/client.py", line 965, in async_execute_cell
    await self._check_raise_for_error(cell, cell_index, exec_reply)
  File "/Library/Frameworks/Python.framework/Versions/3.10/lib/python3.10/site-packages/nbclient/client.py", line 862, in _check_raise_for_error
    raise CellExecutionError.from_cell_and_msg(cell, exec_reply_content)
nbclient.exceptions.CellExecutionError: An error occurred while executing the following cell:
------------------
import zipfile as zf
files = zf.ZipFile("/home/jupyter/SyntheticNAV/dsData.zip", 'r')
files.extractall('/home/jupyter/SyntheticNAV/Data')
files.close()
------------------

[0;31m---------------------------------------------------------------------------[0m
[0;31mFileNotFoundError[0m                         Traceback (most recent call last)
Input [0;32mIn [1][0m, in [0;36m<cell line: 2>[0;34m()[0m
[1;32m      1[0m [38;5;28;01mimport[39;00m [38;5;21;01mzipfile[39;00m [38;5;28;01mas[39;00m [38;5;21;01mzf[39;00m
[0;32m----> 2[0m files [38;5;241m=[39m [43mzf[49m[38;5;241;43m.[39;49m[43mZipFile[49m[43m([49m[38;5;124;43m"[39;49m[38;5;124;43m/home/jupyter/SyntheticNAV/dsData.zip[39;49m[38;5;124;43m"[39;49m[43m,[49m[43m [49m[38;5;124;43m'[39;49m[38;5;124;43mr[39;49m[38;5;124;43m'[39;49m[43m)[49m
[1;32m      3[0m files[38;5;241m.[39mextractall([38;5;124m'[39m[38;5;124m/home/jupyter/SyntheticNAV/Data[39m[38;5;124m'[39m)
[1;32m      4[0m files[38;5;241m.[39mclose()

File [0;32m/Library/Frameworks/Python.framework/Versions/3.10/lib/python3.10/zipfile.py:1249[0m, in [0;36mZipFile.__init__[0;34m(self, file, mode, compression, allowZip64, compresslevel, strict_timestamps)[0m
[1;32m   1247[0m [38;5;28;01mwhile[39;00m [38;5;28;01mTrue[39;00m:
[1;32m   1248[0m     [38;5;28;01mtry[39;00m:
[0;32m-> 1249[0m         [38;5;28mself[39m[38;5;241m.[39mfp [38;5;241m=[39m [43mio[49m[38;5;241;43m.[39;49m[43mopen[49m[43m([49m[43mfile[49m[43m,[49m[43m [49m[43mfilemode[49m[43m)[49m
[1;32m   1250[0m     [38;5;28;01mexcept[39;00m [38;5;167;01mOSError[39;00m:
[1;32m   1251[0m         [38;5;28;01mif[39;00m filemode [38;5;129;01min[39;00m modeDict:

[0;31mFileNotFoundError[0m: [Errno 2] No such file or directory: '/home/jupyter/SyntheticNAV/dsData.zip'
FileNotFoundError: [Errno 2] No such file or directory: '/home/jupyter/SyntheticNAV/dsData.zip'

